<?xml version="1.0" ?>
<!-- =================================================================================== -->
<!-- |    This document was autogenerated by xacro from urdf/pexod.xacro               | -->
<!-- |    EDITING THIS FILE BY HAND IS NOT RECOMMENDED                                 | -->
<!-- =================================================================================== -->
<robot name="pexod" xmlns:xacro="http://www.ros.org/wiki/xacro">
  <!-- <xacro:include filename="$(find pexod_description)/urdf/pexod_control.xacro" /> -->
  <!-- MATERIALS -->
  <material name="Blue">
    <color rgba="0 0 1 1"/>
  </material>
  <material name="Red">
    <color rgba="1 0 0 1"/>
  </material>
  <material name="Green">
    <color rgba="0 1 0 1"/>
  </material>
  <material name="Yellow">
    <color rgba="1 1 0 1"/>
  </material>
  <material name="LightGrey">
    <color rgba="0.6 0.6 0.6 1.0"/>
  </material>
  <!-- END OF MATERIALS -->
  <!-- XACRO MACROS FOR VISUALS AND COLLISIONS -->
  <!-- END OF XACRO MACROS -->
  <!-- TORSO -->
  <link name="base_link">
    <visual>
      <origin rpy="0 0 0" xyz="0 0 0"/>
      <geometry>
        <box size="0.239 0.117 0.095"/>
      </geometry>
      <material name="Blue"/>
    </visual>
    <collision>
      <origin rpy="0 0 0" xyz="0 0 0"/>
      <geometry>
  <!-- END OF LEG LINKS/JOINTS -->
        <box size="0.239 0.117 0.095"/>
      </geometry>
    </collision>
    <inertial>
      <!-- CENTER OF MASS -->
      <origin rpy="0 0 0" xyz="0 0 0"/>
      <!-- <mass value="0.01"/> -->
      <mass value="1.396"/>
      <!-- box inertia: 1/12*m(y^2+z^2), ... -->
      <inertia ixx="0.003" ixy="0" ixz="0" iyy="0.008" iyz="0" izz="0.008"/>
    </inertial>
  </link>
  <joint name="body_camera" type="fixed">
    <parent link="base_link"/>
    <child link="camera_mount"/>
    <origin rpy="0 0 0" xyz="0.1 0 0.025"/>
</joint>

<link name="camera_mount">
    <visual>
      <origin rpy="0 0 0" xyz="0 0 0.11"/>
      <geometry>
        <box size=" 0.05 0.117 0.17"/>
      </geometry>
      <material name="Blue"/>
    </visual>
    <collision>
      <origin rpy="0 0 0" xyz="0 0 0.11"/>
      <geometry>
  <!-- END OF LEG LINKS/JOINTS -->
        <box size=" 0.05 0.117 0.17"/>
      </geometry>
    </collision>
    <inertial>
      <!-- CENTER OF MASS -->
      <origin rpy="0 0 0" xyz="0 0 0.11"/>
      <!-- <mass value="0.01"/> -->
      <mass value="0.50"/>
      <!-- box inertia: 1/12*m(y^2+z^2), ... -->
      <inertia ixx="0.0017" ixy="0" ixz="0" iyy="0.0013" iyz="0" izz="0.00067"/>
    </inertial>
</link>
  <!-- XACRO MACRO FOR LEGS LINKS/JOINTS -->
  <joint name="body_leg_2" type="revolute">
    <parent link="base_link"/>
    <child link="leg_2_1"/>
    <limit effort="1.961" lower="-2.0944" upper="2.0944" velocity="5.236"/>
    <origin rpy="0 0 -0.785" xyz="0.119 0.0585 -0.025"/>
    <!-- <xacro:if value="${index == 5 or index == 4 or index == 3}">
                <axis xyz="0 0 1"/>
            </xacro:if>
            <xacro:if value="${index == 2 or index == 1 or index == 0}"> -->
    <axis xyz="0 0 1"/>
    <!-- </xacro:if> -->
    <dynamics damping="0" friction="0"/>
  </joint>
  <link name="leg_2_1">
    <visual>
      <origin rpy="1.57079632679 0 0" xyz="0 0.0225 0"/>
      <geometry>
        <box size="0.055 0.02 0.045"/>
        <!-- <cylinder length="0.04" radius="0.02"/> -->
      </geometry>
      <material name="Red"/>
    </visual>

    <collision>
      <origin rpy="1.57079632679 0 0" xyz="0 0.0225 0"/>
      <geometry>
        <box size="0.055 0.02 0.045"/>
      </geometry>
    </collision>
    <inertial>
      <!-- CENTER OF MASS -->
      <origin rpy="1.57079632679 0 0" xyz="0 0.0225 0"/>
      <mass value="0.01"/>
      <!-- box inertia: 1/12*m(y^2+z^2), ... -->
      <inertia ixx="2.021e-6" ixy="0" ixz="0" iyy="4.208e-6" iyz="0" izz="2.854e-6"/>
    </inertial>
  </link>
  <joint name="leg_2_1_2" type="revolute">
    <parent link="leg_2_1"/>
    <child link="leg_2_2"/>
    <limit effort="1.961" lower="-2.0944" upper="2.0944" velocity="5.236"/>
    <origin rpy="0 0 0" xyz="0 0.045 0"/>
    <axis xyz="1 0 0"/>
    <dynamics damping="0" friction="0"/>
  </joint>
  <link name="leg_2_2">
    <visual>
      <origin rpy="1.57079632679 0 0" xyz="0 0.045 0"/>
      <geometry>
        <box size="0.044 0.02 0.09"/>
        <!-- <cylinder length="0.09" radius="0.02"/> -->
      </geometry>
      <material name="Blue"/>
    </visual>
    <collision>
      <origin rpy="1.57079632679 0 0" xyz="0 0.045 0"/>
      <geometry>
        <box size="0.044 0.02 0.09"/>
      </geometry>
    </collision>
    <inertial>
      <!-- CENTER OF MASS -->
      <origin rpy="1.57079632679 0 0" xyz="0 0.045 0"/>
      <mass value="0.124"/>
      <!-- box inertia: 1/12*m(y^2+z^2), ... -->
      <inertia ixx="0.00008783" ixy="0" ixz="0" iyy="1.037e-4" iyz="0" izz="2.414e-5"/>
    </inertial>
  </link>
  <joint name="leg_2_2_3" type="revolute">
    <parent link="leg_2_2"/>
    <child link="leg_2_3"/>
    <limit effort="1.961" lower="-2.0944" upper="2.0944" velocity="5.236"/>
    <origin rpy="0 0 0" xyz="0 0.09 0"/>
    <axis xyz="-1 0 0"/>
    <dynamics damping="0" friction="0"/>
  </joint>
  <link name="leg_2_3">
    <visual>
      <origin rpy="0.785 0 0" xyz="0 0.0441941738 -0.0441941738"/>
      <geometry>
        <box size="0.055 0.04 0.125"/>
        <!-- <cylinder length="0.125" radius="0.025"/> -->
      </geometry>
      <material name="Red"/>
    </visual>

    <collision>
      <origin rpy="0.785 0 0" xyz="0 0.0441941738 -0.0441941738"/>
      <geometry>
        <box size="0.055 0.04 0.125"/>
      </geometry>
    </collision>

    <inertial>
      <!-- CENTER OF MASS -->
      <origin rpy="0.785 0 0" xyz="0 0.0441941738 -0.0441941738"/>
      <mass value="0.01"/>
      <!-- box inertia: 1/12*m(y^2+z^2), ... -->
      <inertia ixx="1.435e-5" ixy="0" ixz="0" iyy="1.554e-5" iyz="0" izz="0.00000385"/>
    </inertial>
  </link>

  <joint name="joint_2_eef" type="fixed" dont_collapse="true">
    <parent link="leg_2_3"/>
    <child link="dummy_eef_2"/>
    <origin rpy="0.785 0 0" xyz="0 0.0883883476 -0.0883883476"/>
  </joint>

  <link name="dummy_eef_2">
	<visual>
      <geometry>
        <sphere radius="0.005"/>
      </geometry>
      <material name="Green"/>
    </visual>
    <inertial>
      <!-- CENTER OF MASS -->
      <origin rpy="0 0 0" xyz="0 0 0"/>
      <mass value="0"/>
      <inertia ixx="0" ixy="0" ixz="0" iyy="0" iyz="0" izz="0"/>
    </inertial>
  </link>

  <joint name="body_leg_3" type="revolute">
    <parent link="base_link"/>
    <child link="leg_3_1"/>
    <limit effort="1.961" lower="-2.0944" upper="2.0944" velocity="5.236"/>
    <origin rpy="0 0 0.785" xyz="0.119 -0.0585 -0.025"/>
    <!-- <xacro:if value="${index == 5 or index == 4 or index == 3}">
                <axis xyz="0 0 1"/>
            </xacro:if>
            <xacro:if value="${index == 2 or index == 1 or index == 0}"> -->
    <axis xyz="0 0 -1"/>
    <!-- </xacro:if> -->
    <dynamics damping="0" friction="0"/>
  </joint>
  <link name="leg_3_1">
    <visual>
      <origin rpy="1.57079632679 0 0" xyz="0 -0.0225 0"/>
      <geometry>
        <box size="0.055 0.02 0.045"/>
        <!-- <cylinder length="0.04" radius="0.02"/> -->
      </geometry>
      <material name="Red"/>
    </visual>
    <collision>
      <origin rpy="1.57079632679 0 0" xyz="0 -0.0225 0"/>
      <geometry>
        <box size="0.055 0.02 0.045"/>
      </geometry>
    </collision>
    <inertial>
      <!-- CENTER OF MASS -->
      <origin rpy="1.57079632679 0 0" xyz="0 -0.0225 0"/>
      <mass value="0.01"/>
      <!-- box inertia: 1/12*m(y^2+z^2), ... -->
      <inertia ixx="2.021e-6" ixy="0" ixz="0" iyy="4.208e-6" iyz="0" izz="2.854e-6"/>
    </inertial>
  </link>
  <joint name="leg_3_1_2" type="revolute">
    <parent link="leg_3_1"/>
    <child link="leg_3_2"/>
    <limit effort="1.961" lower="-2.0944" upper="2.0944" velocity="5.236"/>
    <origin rpy="0 0 0" xyz="0 -0.045 0"/>
    <axis xyz="-1 0 0"/>
    <dynamics damping="0" friction="0"/>
  </joint>
  <link name="leg_3_2">
    <visual>
      <origin rpy="1.57079632679 0 0" xyz="0 -0.045 0"/>
      <geometry>
        <box size="0.044 0.02 0.09"/>
        <!-- <cylinder length="0.09" radius="0.02"/> -->
      </geometry>
      <material name="Blue"/>
    </visual>
    <collision>
      <origin rpy="1.57079632679 0 0" xyz="0 -0.045 0"/>
      <geometry>
        <box size="0.044 0.02 0.09"/>
      </geometry>
    </collision>
    <inertial>
      <!-- CENTER OF MASS -->
      <origin rpy="1.57079632679 0 0" xyz="0 -0.045 0"/>
      <mass value="0.124"/>
      <!-- box inertia: 1/12*m(y^2+z^2), ... -->
      <inertia ixx="0.00008783" ixy="0" ixz="0" iyy="1.037e-4" iyz="0" izz="2.414e-5"/>
    </inertial>
  </link>
  <joint name="leg_3_2_3" type="revolute">
    <parent link="leg_3_2"/>
    <child link="leg_3_3"/>
    <limit effort="1.961" lower="-2.0944" upper="2.0944" velocity="5.236"/>
    <origin rpy="0 0 0" xyz="0 -0.09 0"/>
    <axis xyz="1 0 0"/>
    <dynamics damping="0" friction="0"/>
  </joint>
  <link name="leg_3_3">
    <visual>
      <origin rpy="-0.785 0 0" xyz="0 -0.0441941738 -0.0441941738"/>
      <geometry>
        <box size="0.055 0.04 0.125"/>
        <!-- <cylinder length="0.125" radius="0.025"/> -->
      </geometry>
      <material name="Red"/>
    </visual>

    <collision>
      <origin rpy="-0.785 0 0" xyz="0 -0.0441941738 -0.0441941738"/>
      <geometry>
        <box size="0.055 0.04 0.125"/>
      </geometry>
    </collision>

    <inertial>
      <!-- CENTER OF MASS -->
      <origin rpy="-0.785 0 0" xyz="0 -0.0441941738 -0.0441941738"/>
      <mass value="0.01"/>
      <!-- box inertia: 1/12*m(y^2+z^2), ... -->
      <inertia ixx="1.435e-5" ixy="0" ixz="0" iyy="1.554e-5" iyz="0" izz="0.00000385"/>
    </inertial>
  </link>

  <joint name="joint_3_eef" type="fixed" dont_collapse="true">
    <parent link="leg_3_3"/>
    <child link="dummy_eef_3"/>
    <origin rpy="-0.785 0 0" xyz="0 -0.0883883476 -0.0883883476"/>
  </joint>

  <link name="dummy_eef_3">
  <visual>
      <geometry>
        <sphere radius="0.005"/>
      </geometry>
      <material name="Green"/>
    </visual>
    <inertial>
      <!-- CENTER OF MASS -->
      <origin rpy="0 0 0" xyz="0 0 0"/>
      <mass value="0"/>
      <inertia ixx="0" ixy="0" ixz="0" iyy="0" iyz="0" izz="0"/>
    </inertial>
  </link>

  <joint name="body_leg_0" type="revolute">
    <parent link="base_link"/>
    <child link="leg_0_1"/>
    <limit effort="1.961" lower="-2.0944" upper="2.0944" velocity="5.236"/>
    <origin rpy="0 0 0.785" xyz="-0.119 0.0585 -0.025"/>
    <!-- <xacro:if value="${index == 5 or index == 4 or index == 3}">
                <axis xyz="0 0 1"/>
            </xacro:if>
            <xacro:if value="${index == 2 or index == 1 or index == 0}"> -->
    <axis xyz="0 0 1"/>
    <!-- </xacro:if> -->
    <dynamics damping="0" friction="0"/>
  </joint>
  <link name="leg_0_1">
    <visual>
      <origin rpy="1.57079632679 0 0" xyz="0 0.0225 0"/>
      <geometry>
        <box size="0.055 0.02 0.045"/>
        <!-- <cylinder length="0.04" radius="0.02"/> -->
      </geometry>
      <material name="Red"/>
    </visual>
    <collision>
      <origin rpy="1.57079632679 0 0" xyz="0 0.0225 0"/>
      <geometry>
        <box size="0.055 0.02 0.045"/>
      </geometry>
    </collision>
    <inertial>
      <!-- CENTER OF MASS -->
      <origin rpy="1.57079632679 0 0" xyz="0 0.0225 0"/>
      <mass value="0.01"/>
      <!-- box inertia: 1/12*m(y^2+z^2), ... -->
      <inertia ixx="2.021e-6" ixy="0" ixz="0" iyy="4.208e-6" iyz="0" izz="2.854e-6"/>
    </inertial>
  </link>
  <joint name="leg_0_1_2" type="revolute">
    <parent link="leg_0_1"/>
    <child link="leg_0_2"/>
    <limit effort="1.961" lower="-2.0944" upper="2.0944" velocity="5.236"/>
    <origin rpy="0 0 0" xyz="0 0.045 0"/>
    <axis xyz="1 0 0"/>
    <dynamics damping="0" friction="0"/>
  </joint>
  <link name="leg_0_2">
    <visual>
      <origin rpy="1.57079632679 0 0" xyz="0 0.045 0"/>
      <geometry>
        <box size="0.044 0.02 0.09"/>
        <!-- <cylinder length="0.09" radius="0.02"/> -->
      </geometry>
      <material name="Blue"/>
    </visual>
    <collision>
      <origin rpy="1.57079632679 0 0" xyz="0 0.045 0"/>
      <geometry>
        <box size="0.044 0.02 0.09"/>
      </geometry>
    </collision>
    <inertial>
      <!-- CENTER OF MASS -->
      <origin rpy="1.57079632679 0 0" xyz="0 0.045 0"/>
      <mass value="0.124"/>
      <!-- box inertia: 1/12*m(y^2+z^2), ... -->
      <inertia ixx="0.00008783" ixy="0" ixz="0" iyy="1.037e-4" iyz="0" izz="2.414e-5"/>
    </inertial>
  </link>
  <joint name="leg_0_2_3" type="revolute">
    <parent link="leg_0_2"/>
    <child link="leg_0_3"/>
    <limit effort="1.961" lower="-2.0944" upper="2.0944" velocity="5.236"/>
    <origin rpy="0 0 0" xyz="0 0.09 0"/>
    <axis xyz="-1 0 0"/>
    <dynamics damping="0" friction="0"/>
  </joint>
  <link name="leg_0_3">
    <visual>
      <origin rpy="0.785 0 0" xyz="0 0.0441941738 -0.0441941738"/>
      <geometry>
        <box size="0.055 0.04 0.125"/>
        <!-- <cylinder length="0.125" radius="0.025"/> -->
      </geometry>
      <material name="Red"/>
    </visual>

    <collision>
      <origin rpy="0.785 0 0" xyz="0 0.0441941738 -0.0441941738"/>
      <geometry>
        <box size="0.055 0.04 0.125"/>
      </geometry>
    </collision>
 
    <inertial>
      <!-- CENTER OF MASS -->
      <origin rpy="0.785 0 0" xyz="0 0.0441941738 -0.0441941738"/>
      <mass value="0.01"/>
      <!-- box inertia: 1/12*m(y^2+z^2), ... -->
      <inertia ixx="1.435e-5" ixy="0" ixz="0" iyy="1.554e-5" iyz="0" izz="0.00000385"/>
    </inertial>
  </link>

  <joint name="joint_0_eef" type="fixed" dont_collapse="true">
    <parent link="leg_0_3"/>
    <child link="dummy_eef_0"/>
    <origin rpy="0.785 0 0" xyz="0 0.0883883476 -0.0883883476"/>
  </joint>

  <link name="dummy_eef_0">
  <visual>
      <geometry>
        <sphere radius="0.005"/>
      </geometry>
      <material name="Green"/>
    </visual>
    <inertial>
      <!-- CENTER OF MASS -->
      <origin rpy="0 0 0" xyz="0 0 0"/>
      <mass value="0"/>
      <inertia ixx="0" ixy="0" ixz="0" iyy="0" iyz="0" izz="0"/>
    </inertial>
  </link>

  <joint name="body_leg_5" type="revolute">
    <parent link="base_link"/>
    <child link="leg_5_1"/>
    <limit effort="1.961" lower="-2.0944" upper="2.0944" velocity="5.236"/>
    <origin rpy="0 0 -0.785" xyz="-0.119 -0.0585 -0.025"/>
    <!-- <xacro:if value="${index == 5 or index == 4 or index == 3}">
                <axis xyz="0 0 1"/>
            </xacro:if>
            <xacro:if value="${index == 2 or index == 1 or index == 0}"> -->
    <axis xyz="0 0 -1"/>
    <!-- </xacro:if> -->
    <dynamics damping="0" friction="0"/>
  </joint>
  <link name="leg_5_1">
    <visual>
      <origin rpy="1.57079632679 0 0" xyz="0 -0.0225 0"/>
      <geometry>
        <box size="0.055 0.02 0.045"/>
        <!-- <cylinder length="0.04" radius="0.02"/> -->
      </geometry>
      <material name="Red"/>
    </visual>
    <collision>
      <origin rpy="1.57079632679 0 0" xyz="0 -0.0225 0"/>
      <geometry>
        <box size="0.055 0.02 0.045"/>
      </geometry>
    </collision>
    <inertial>
      <!-- CENTER OF MASS -->
      <origin rpy="1.57079632679 0 0" xyz="0 -0.0225 0"/>
      <mass value="0.01"/>
      <!-- box inertia: 1/12*m(y^2+z^2), ... -->
      <inertia ixx="2.021e-6" ixy="0" ixz="0" iyy="4.208e-6" iyz="0" izz="2.854e-6"/>
    </inertial>
  </link>
  <joint name="leg_5_1_2" type="revolute">
    <parent link="leg_5_1"/>
    <child link="leg_5_2"/>
    <limit effort="1.961" lower="-2.0944" upper="2.0944" velocity="5.236"/>
    <origin rpy="0 0 0" xyz="0 -0.045 0"/>
    <axis xyz="-1 0 0"/>
    <dynamics damping="0" friction="0"/>
  </joint>
  <link name="leg_5_2">
    <visual>
      <origin rpy="1.57079632679 0 0" xyz="0 -0.045 0"/>
      <geometry>
        <box size="0.044 0.02 0.09"/>
        <!-- <cylinder length="0.09" radius="0.02"/> -->
      </geometry>
      <material name="Blue"/>
    </visual>
    <collision>
      <origin rpy="1.57079632679 0 0" xyz="0 -0.045 0"/>
      <geometry>
        <box size="0.044 0.02 0.09"/>
      </geometry>
    </collision>
    <inertial>
      <!-- CENTER OF MASS -->
      <origin rpy="1.57079632679 0 0" xyz="0 -0.045 0"/>
      <mass value="0.124"/>
      <!-- box inertia: 1/12*m(y^2+z^2), ... -->
      <inertia ixx="0.00008783" ixy="0" ixz="0" iyy="1.037e-4" iyz="0" izz="2.414e-5"/>
    </inertial>
  </link>
  <joint name="leg_5_2_3" type="revolute">
    <parent link="leg_5_2"/>
    <child link="leg_5_3"/>
    <limit effort="1.961" lower="-2.0944" upper="2.0944" velocity="5.236"/>
    <origin rpy="0 0 0" xyz="0 -0.09 0"/>
    <axis xyz="1 0 0"/>
    <dynamics damping="0" friction="0"/>
  </joint>
  <link name="leg_5_3">
    <visual>
      <origin rpy="-0.785 0 0" xyz="0 -0.0441941738 -0.0441941738"/>
      <geometry>
        <box size="0.055 0.04 0.125"/>
        <!-- <cylinder length="0.125" radius="0.025"/> -->
      </geometry>
      <material name="Red"/>
    </visual>

    <collision>
      <origin rpy="-0.785 0 0" xyz="0 -0.0441941738 -0.0441941738"/>
      <geometry>
        <box size="0.055 0.04 0.125"/>
      </geometry>
    </collision>

    <inertial>
      <!-- CENTER OF MASS -->
      <origin rpy="-0.785 0 0" xyz="0 -0.0441941738 -0.0441941738"/>
      <mass value="0.01"/>
      <!-- box inertia: 1/12*m(y^2+z^2), ... -->
      <inertia ixx="1.435e-5" ixy="0" ixz="0" iyy="1.554e-5" iyz="0" izz="0.00000385"/>
    </inertial>
  </link>

  <joint name="joint_5_eef" type="fixed" dont_collapse="true">
    <parent link="leg_5_3"/>
    <child link="dummy_eef_5"/>
    <origin rpy="-0.785 0 0" xyz="0 -0.0883883476 -0.0883883476"/>
  </joint>

  <link name="dummy_eef_5">
  <visual>
      <geometry>
        <sphere radius="0.005"/>
      </geometry>
      <material name="Green"/>
    </visual>
    <inertial>
      <!-- CENTER OF MASS -->
      <origin rpy="0 0 0" xyz="0 0 0"/>
      <mass value="0"/>
      <inertia ixx="0" ixy="0" ixz="0" iyy="0" iyz="0" izz="0"/>
    </inertial>
  </link>

  <joint name="body_leg_1" type="revolute">
    <parent link="base_link"/>
    <child link="leg_1_1"/>
    <limit effort="1.961" lower="-2.0944" upper="2.0944" velocity="5.236"/>
    <origin rpy="0 0 0" xyz="0 0.0915 -0.025"/>
    <!-- <xacro:if value="${index == 5 or index == 4 or index == 3}">
                <axis xyz="0 0 1"/>
            </xacro:if>
            <xacro:if value="${index == 2 or index == 1 or index == 0}"> -->
    <axis xyz="0 0 1"/>
    <!-- </xacro:if> -->
    <dynamics damping="0" friction="0"/>
  </joint>
  <link name="leg_1_1">
    <visual>
      <origin rpy="1.57079632679 0 0" xyz="0 0.0225 0"/>
      <geometry>
        <box size="0.055 0.02 0.045"/>
        <!-- <cylinder length="0.04" radius="0.02"/> -->
      </geometry>
      <material name="Red"/>
    </visual>
    <collision>
      <origin rpy="1.57079632679 0 0" xyz="0 0.0225 0"/>
      <geometry>
        <box size="0.055 0.02 0.045"/>
      </geometry>
    </collision>
    <inertial>
      <!-- CENTER OF MASS -->
      <origin rpy="1.57079632679 0 0" xyz="0 0.0225 0"/>
      <mass value="0.01"/>
      <!-- box inertia: 1/12*m(y^2+z^2), ... -->
      <inertia ixx="2.021e-6" ixy="0" ixz="0" iyy="4.208e-6" iyz="0" izz="2.854e-6"/>
    </inertial>
  </link>
  <joint name="leg_1_1_2" type="revolute">
    <parent link="leg_1_1"/>
    <child link="leg_1_2"/>
    <limit effort="1.961" lower="-2.0944" upper="2.0944" velocity="5.236"/>
    <origin rpy="0 0 0" xyz="0 0.045 0"/>
    <axis xyz="1 0 0"/>
    <dynamics damping="0" friction="0"/>
  </joint>
  <link name="leg_1_2">
    <visual>
      <origin rpy="1.57079632679 0 0" xyz="0 0.045 0"/>
      <geometry>
        <box size="0.044 0.02 0.09"/>
        <!-- <cylinder length="0.09" radius="0.02"/> -->
      </geometry>
      <material name="Blue"/>
    </visual>
    <collision>
      <origin rpy="1.57079632679 0 0" xyz="0 0.045 0"/>
      <geometry>
        <box size="0.044 0.02 0.09"/>
      </geometry>
    </collision>
    <inertial>
      <!-- CENTER OF MASS -->
      <origin rpy="1.57079632679 0 0" xyz="0 0.045 0"/>
      <mass value="0.124"/>
      <!-- box inertia: 1/12*m(y^2+z^2), ... -->
      <inertia ixx="0.00008783" ixy="0" ixz="0" iyy="1.037e-4" iyz="0" izz="2.414e-5"/>
    </inertial>
  </link>
  <joint name="leg_1_2_3" type="revolute">
    <parent link="leg_1_2"/>
    <child link="leg_1_3"/>
    <limit effort="1.961" lower="-2.0944" upper="2.0944" velocity="5.236"/>
    <origin rpy="0 0 0" xyz="0 0.09 0"/>
    <axis xyz="-1 0 0"/>
    <dynamics damping="0" friction="0"/>
  </joint>
  <link name="leg_1_3">
    <visual>
      <origin rpy="0.785 0 0" xyz="0 0.0441941738 -0.0441941738"/>
      <geometry>
        <box size="0.055 0.04 0.125"/>
        <!-- <cylinder length="0.125" radius="0.025"/> -->
      </geometry>
      <material name="Red"/>
    </visual>

    <collision>
      <origin rpy="0.785 0 0" xyz="0 0.0441941738 -0.0441941738"/>
      <geometry>
        <box size="0.055 0.04 0.125"/>
      </geometry>
    </collision>

    <inertial>
      <!-- CENTER OF MASS -->
      <origin rpy="0.785 0 0" xyz="0 0.0441941738 -0.0441941738"/>
      <mass value="0.01"/>
      <!-- box inertia: 1/12*m(y^2+z^2), ... -->
      <inertia ixx="1.435e-5" ixy="0" ixz="0" iyy="1.554e-5" iyz="0" izz="0.00000385"/>
    </inertial>
  </link>

  <joint name="joint_1_eef" type="fixed" dont_collapse="true">
    <parent link="leg_1_3"/>
    <child link="dummy_eef_1"/>
    <origin rpy="0.785 0 0" xyz="0 0.0883883476 -0.0883883476"/>
  </joint>

  <link name="dummy_eef_1">
  <visual>
      <geometry>
        <sphere radius="0.005"/>
      </geometry>
      <material name="Green"/>
    </visual>
    <inertial>
      <!-- CENTER OF MASS -->
      <origin rpy="0 0 0" xyz="0 0 0"/>
      <mass value="0"/>
      <inertia ixx="0" ixy="0" ixz="0" iyy="0" iyz="0" izz="0"/>
    </inertial>
  </link>

  <joint name="body_leg_4" type="revolute">
    <parent link="base_link"/>
    <child link="leg_4_1"/>
    <limit effort="1.961" lower="-2.0944" upper="2.0944" velocity="5.236"/>
    <origin rpy="0 0 0" xyz="0 -0.0915 -0.025"/>
    <!-- <xacro:if value="${index == 5 or index == 4 or index == 3}">
                <axis xyz="0 0 1"/>
            </xacro:if>
            <xacro:if value="${index == 2 or index == 1 or index == 0}"> -->
    <axis xyz="0 0 -1"/>
    <!-- </xacro:if> -->
    <dynamics damping="0" friction="0"/>
  </joint>
  <link name="leg_4_1">
    <visual>
      <origin rpy="1.57079632679 0 0" xyz="0 -0.0225 0"/>
      <geometry>
        <box size="0.055 0.02 0.045"/>
        <!-- <cylinder length="0.04" radius="0.02"/> -->
      </geometry>
      <material name="Red"/>
    </visual>
    <collision>
      <origin rpy="1.57079632679 0 0" xyz="0 -0.0225 0"/>
      <geometry>
        <box size="0.055 0.02 0.045"/>
      </geometry>
    </collision>
    <inertial>
      <!-- CENTER OF MASS -->
      <origin rpy="1.57079632679 0 0" xyz="0 -0.0225 0"/>
      <mass value="0.01"/>
      <!-- box inertia: 1/12*m(y^2+z^2), ... -->
      <inertia ixx="2.021e-6" ixy="0" ixz="0" iyy="4.208e-6" iyz="0" izz="2.854e-6"/>
    </inertial>
  </link>
  <joint name="leg_4_1_2" type="revolute">
    <parent link="leg_4_1"/>
    <child link="leg_4_2"/>
    <limit effort="1.961" lower="-2.0944" upper="2.0944" velocity="5.236"/>
    <origin rpy="0 0 0" xyz="0 -0.045 0"/>
    <axis xyz="-1 0 0"/>
    <dynamics damping="0" friction="0"/>
  </joint>
  <link name="leg_4_2">
    <visual>
      <origin rpy="1.57079632679 0 0" xyz="0 -0.045 0"/>
      <geometry>
        <box size="0.044 0.02 0.09"/>
        <!-- <cylinder length="0.09" radius="0.02"/> -->
      </geometry>
      <material name="Blue"/>
    </visual>
    <collision>
      <origin rpy="1.57079632679 0 0" xyz="0 -0.045 0"/>
      <geometry>
        <box size="0.044 0.02 0.09"/>
      </geometry>
    </collision>
    <inertial>
      <!-- CENTER OF MASS -->
      <origin rpy="1.57079632679 0 0" xyz="0 -0.045 0"/>
      <mass value="0.124"/>
      <!-- box inertia: 1/12*m(y^2+z^2), ... -->
      <inertia ixx="0.00008783" ixy="0" ixz="0" iyy="1.037e-4" iyz="0" izz="2.414e-5"/>
    </inertial>
  </link>
  <joint name="leg_4_2_3" type="revolute">
    <parent link="leg_4_2"/>
    <child link="leg_4_3"/>
    <limit effort="1.961" lower="-2.0944" upper="2.0944" velocity="5.236"/>
    <origin rpy="0 0 0" xyz="0 -0.09 0"/>
    <axis xyz="1 0 0"/>
    <dynamics damping="0" friction="0"/>
  </joint>
  <link name="leg_4_3">
    <visual>
      <origin rpy="-0.785 0 0" xyz="0 -0.0441941738 -0.0441941738"/>
      <geometry>
        <box size="0.055 0.04 0.125"/>
        <!-- <cylinder length="0.125" radius="0.025"/> -->
      </geometry>
      <material name="Red"/>
    </visual>

    <collision>
      <origin rpy="-0.785 0 0" xyz="0 -0.0441941738 -0.0441941738"/>
      <geometry>
        <box size="0.055 0.04 0.125"/>
      </geometry>
    </collision>

    <inertial>
      <!-- CENTER OF MASS -->
      <origin rpy="-0.785 0 0" xyz="0 -0.0441941738 -0.0441941738"/>
      <mass value="0.01"/>
      <!-- box inertia: 1/12*m(y^2+z^2), ... -->
      <inertia ixx="1.435e-5" ixy="0" ixz="0" iyy="1.554e-5" iyz="0" izz="0.00000385"/>
    </inertial>
  </link>

  <joint name="joint_4_eef" type="fixed" dont_collapse="true">
    <parent link="leg_4_3"/>
    <child link="dummy_eef_4"/>
    <origin rpy="-0.785 0 0" xyz="0 -0.0883883476 -0.0883883476"/>
  </joint>

  <link name="dummy_eef_4">
    <visual>
      <geometry>
        <sphere radius="0.005"/>
      </geometry>
      <material name="Green"/>
    </visual>
    <inertial>
      <!-- CENTER OF MASS -->
      <origin rpy="0 0 0" xyz="0 0 0"/>
      <mass value="0"/>
      <inertia ixx="0" ixy="0" ixz="0" iyy="0" iyz="0" izz="0"/>
    </inertial>
  </link>
  <!-- END OF LEG LINKS/JOINTS -->
</robot>